<?xml version="1.0"?>
<!--
Software License Agreement (BSD)

\file      wheel.urdf.xacro
\authors   Paul Bovbel <pbovbel@clearpathrobotics.com>
\copyright Copyright (c) 2015, Clearpath Robotics, Inc., All rights reserved.

Redistribution and use in source and binary forms, with or without modification, are permitted provided that
the following conditions are met:
 * Redistributions of source code must retain the above copyright notice, this list of conditions and the
   following disclaimer.
 * Redistributions in binary form must reproduce the above copyright notice, this list of conditions and the
   following disclaimer in the documentation and/or other materials provided with the distribution.
 * Neither the name of Clearpath Robotics nor the names of its contributors may be used to endorse or promote
   products derived from this software without specific prior written permission.

THIS SOFTWARE IS PROVIDED BY THE COPYRIGHT HOLDERS AND CONTRIBUTORS "AS IS" AND ANY EXPRESS OR IMPLIED WAR-
RANTIES, INCLUDING, BUT NOT LIMITED TO, THE IMPLIED WARRANTIES OF MERCHANTABILITY AND FITNESS FOR A PARTICULAR
PURPOSE ARE DISCLAIMED. IN NO EVENT SHALL THE COPYRIGHT HOLDER OR CONTRIBUTORS BE LIABLE FOR ANY DIRECT, IN-
DIRECT, INCIDENTAL, SPECIAL, EXEMPLARY, OR CONSEQUENTIAL DAMAGES (INCLUDING, BUT NOT LIMITED TO, PROCUREMENT
OF SUBSTITUTE GOODS OR SERVICES; LOSS OF USE, DATA, OR PROFITS; OR BUSINESS INTERRUPTION) HOWEVER CAUSED AND
ON ANY THEORY OF LIABILITY, WHETHER IN CONTRACT, STRICT LIABILITY, OR TORT (INCLUDING NEGLIGENCE OR OTHERWISE)
ARISING IN ANY WAY OUT OF THE USE OF THIS SOFTWARE, EVEN IF ADVISED OF THE POSSIBILITY OF SUCH DAMAGE.
-->
<robot xmlns:xacro="http://ros.org/wiki/xacro" name="duckiebot_wheel">

	<xacro:macro name="duckiebot_wheel" params="wheel_prefix *joint_pose">
		<link name="${wheel_prefix}_wheel">
			   <max_contacts>2</max_contacts>
			    <collision name="collision">
			   <max_contacts>2</max_contacts>
			      <origin xyz="0 0 0" rpy="0 1.5707 1.5707"/>
			      <geometry>
				<cylinder radius="0.1" length="0.05"/>
			      </geometry>
			    </collision>
			    <visual name="right_wheel_visual">
			      <origin xyz="0 0 0" rpy="0 1.5707 1.5707"/>
			      <geometry>
				<cylinder radius="0.1" length="0.05"/>
			      </geometry>
			    </visual>
			    <inertial>
			      <origin xyz="0 0 0" rpy="0 1.5707 1.5707"/>
			      <mass value="5"/>
			      <inertia
				ixx="0.02" ixy="0.0" ixz="0.0"
				iyy="0.02" iyz="0.0"
				izz="0.02"/>
			    </inertial>
		</link>

		<gazebo reference="${wheel_prefix}_wheel">
			<material>Gazebo/Black</material>
			<mu1 value="1.0"/>
			<mu2 value="1.0"/>
			<kp value="10000000.0" />
			<kd value="1.0" />
			<fdir1 value="1 0 0"/>

		</gazebo>


		<joint name="${wheel_prefix}_wheel_hinge" type="continuous">
			<parent link="base_link"/>
			<child link="${wheel_prefix}_wheel"/>
			<xacro:insert_block name="joint_pose"/>
			<axis xyz="0 1 0" rpy="0 0 0" />
		        <!--limit effort="10000" velocity="1000"/>
		        <joint_properties damping="1.0" friction="1.0"/-->
		</joint>

		<transmission name="${wheel_prefix}_wheel_trans" type="SimpleTransmission">
			<type>transmission_interface/SimpleTransmission</type>
			<actuator name="${wheel_prefix}_wheel_motor">
				<mechanicalReduction>1</mechanicalReduction>
			</actuator>
			<joint name="${wheel_prefix}_wheel_hinge">
				<hardwareInterface>VelocityJointInterface</hardwareInterface>
			</joint>
		</transmission>

	</xacro:macro>
</robot>
